{"trial_id": "1", "hyperparameters": {"space": [{"class_name": "Int", "config": {"name": "conv1", "default": null, "conditions": [], "min_value": 8, "max_value": 64, "step": 8, "sampling": "linear"}}, {"class_name": "Int", "config": {"name": "conv2", "default": null, "conditions": [], "min_value": 16, "max_value": 128, "step": 16, "sampling": "linear"}}, {"class_name": "Float", "config": {"name": "dropout_rate", "default": 0.1, "conditions": [], "min_value": 0.1, "max_value": 0.5, "step": 0.1, "sampling": "linear"}}, {"class_name": "Int", "config": {"name": "dense1", "default": null, "conditions": [], "min_value": 32, "max_value": 256, "step": 32, "sampling": "linear"}}], "values": {"conv1": 24, "conv2": 96, "dropout_rate": 0.1, "dense1": 128}}, "metrics": {"metrics": {}}, "score": null, "best_step": 0, "status": "FAILED", "message": "Traceback (most recent call last):\n  File \"c:\\Users\\jagad\\AppData\\Local\\Programs\\Python\\Python310\\lib\\site-packages\\keras_tuner\\src\\engine\\base_tuner.py\", line 274, in _try_run_and_update_trial\n    self._run_and_update_trial(trial, *fit_args, **fit_kwargs)\n  File \"c:\\Users\\jagad\\AppData\\Local\\Programs\\Python\\Python310\\lib\\site-packages\\keras_tuner\\src\\engine\\base_tuner.py\", line 239, in _run_and_update_trial\n    results = self.run_trial(trial, *fit_args, **fit_kwargs)\n  File \"c:\\Users\\jagad\\AppData\\Local\\Programs\\Python\\Python310\\lib\\site-packages\\keras_tuner\\src\\engine\\tuner.py\", line 314, in run_trial\n    obj_value = self._build_and_fit_model(trial, *args, **copied_kwargs)\n  File \"c:\\Users\\jagad\\AppData\\Local\\Programs\\Python\\Python310\\lib\\site-packages\\keras_tuner\\src\\engine\\tuner.py\", line 233, in _build_and_fit_model\n    results = self.hypermodel.fit(hp, model, *args, **kwargs)\n  File \"c:\\Users\\jagad\\AppData\\Local\\Programs\\Python\\Python310\\lib\\site-packages\\keras_tuner\\src\\engine\\hypermodel.py\", line 149, in fit\n    return model.fit(*args, **kwargs)\n  File \"c:\\Users\\jagad\\AppData\\Local\\Programs\\Python\\Python310\\lib\\site-packages\\keras\\src\\utils\\traceback_utils.py\", line 122, in error_handler\n    raise e.with_traceback(filtered_tb) from None\n  File \"c:\\Users\\jagad\\AppData\\Local\\Programs\\Python\\Python310\\lib\\site-packages\\keras\\src\\utils\\traceback_utils.py\", line 117, in error_handler\n    return fn(*args, **kwargs)\nTypeError: TensorFlowTrainer.fit() got an unexpected keyword argument 'validation_set'\n"}